
<robot name="quadruped">

  <link name="body">
    <visual>
      <geometry>
        <cylinder radius="0.08" length="0.06"/>
      </geometry>
      <origin xyz="0 0 0"/>
      <material name="blue">
        <color rgba="0 0 1 1"/>
      </material>
    </visual>
    <collision>
      <geometry>
        <cylinder radius="0.08" length="0.06"/>
      </geometry>
      <origin xyz="0 0 0"/>
    </collision>
    <inertial>
      <mass value="0.01"/>
      <inertia ixx="0.0001" ixy="0.0" ixz="0.0" iyy="0.0001" iyz="0.0" izz="0.0001"/>
    </inertial>
  </link>


    <link name="h0">
    <visual>
      <geometry>
        <cylinder radius="0.01" length="0.12"/>
      </geometry>
      <origin rpy="0 1.5707963267948966 0" xyz="0.06 0  0" />
      <material name="red">
        <color rgba="1 0 0 1"/>
      </material>
    </visual>
    <collision>
      <geometry>
        <cylinder radius="0.01" length="0.12"/>
      </geometry>
      <origin rpy="0 1.5707963267948966 0" xyz="0.06 0 0" />
    </collision>
    <inertial>
      <mass value="0.1"/>
      <inertia ixx="0.0001" ixy="0.0" ixz="0.0" iyy="0.0001" iyz="0.0" izz="0.0001"/>
    </inertial>
  </link>

  <joint name="h0_to_body" type="fixed">
    <origin rpy="0 0 0" xyz="0 0 0"/>
    <parent link="body"/>
    <child link="h0"/>
  </joint>

  
  <link name="a0">
    <visual>
      <geometry>
        <cylinder radius="0.015" length="0.13"/>
      </geometry>
      <origin rpy="0 1.5707963267948966 0" xyz="0.065 0  0" />
      <material name="red">
        <color rgba="1 0 0 1"/>
      </material>
    </visual>
    <collision>
      <geometry>
        <cylinder radius="0.015" length="0.13"/>
      </geometry>
      <origin rpy="0 1.5707963267948966 0" xyz="0.065 0 0" />
    </collision>
    <inertial>
      <mass value="0.1"/>
      <inertia ixx="0.0001" ixy="0.0" ixz="0.0" iyy="0.0001" iyz="0.0" izz="0.0001"/>
    </inertial>
  </link>

  <joint name="a0_to_body" type="fixed">
    <origin rpy="0 0 0.7853981633974483" xyz="0 0 0"/>
    <parent link="body"/>
    <child link="a0"/>
  </joint>

  <!-- B -->

  <link name="b0">
    <visual>
      <geometry>
        <cylinder radius="0.015" length="0.05"/>
      </geometry>
      <origin rpy="0 1.5707963267948966 0" xyz="0.025 0 0" />
      <material name="green">
        <color rgba="0 1 0 1"/>
      </material>
    </visual>
    <collision>
      <geometry>
        <cylinder radius="0.015" length="0.05"/>
      </geometry>
      <origin rpy="0 1.5707963267948966 0" xyz="0.025 0 0" />
    </collision>
    <inertial>
      <mass value="0.1"/>
      <inertia ixx="0.0001" ixy="0.0" ixz="0.0" iyy="0.0001" iyz="0.0" izz="0.0001"/>
    </inertial>

  </link>

  <joint name="u0" type="revolute">
    <origin rpy="0 0 0" xyz="0.13 0 0"/>
    <parent link="a0"/>
    <child link="b0"/>
    <axis xyz="0 0 1"/>
    <limit effort="100" lower="-3.14" upper="3.14"  velocity="100"/>
  </joint>

  <link name="c0">
    <visual>
      <geometry>
        <cylinder radius="0.015" length="0.08"/>
      </geometry>
      <origin rpy="0 1.5707963267948966 0" xyz="0.04 0 0" />
      <material name="cyan">
        <color rgba="0 1 1 1"/>
      </material>
    </visual>
    <collision>
      <geometry>
        <cylinder radius="0.015" length="0.08"/>
      </geometry>
      <origin rpy="0 1.5707963267948966 0" xyz="0.04 0 0" />
    </collision>
    <inertial>
      <mass value="0.1"/>
      <inertia ixx="0.0001" ixy="0.0" ixz="0.0" iyy="0.0001" iyz="0.0" izz="0.0001"/>
    </inertial>

  </link>

  <joint name="v0" type="revolute">
    <origin rpy="0 0 0" xyz="0.05 0 0"/>
    <parent link="b0"/>
    <child link="c0"/>
    <axis xyz="0 1 0"/>
    <limit effort="100" lower="-3.14" upper="3.14"  velocity="100"/>
  </joint>

  <link name="d0">
    <visual>
      <geometry>
        <cylinder radius="0.015" length="0.14"/>
      </geometry>
      <origin rpy="0 1.5707963267948966 0" xyz="0.07 0 0" />
      <material name="jaune">
        <color rgba="1 1 0 1"/>
      </material>
    </visual>
    <collision>
      <geometry>
        <cylinder radius="0.015" length="0.14"/>
      </geometry>
      <origin rpy="0 1.5707963267948966 0" xyz="0.07 0 0" />
    </collision>
    <inertial>
      <mass value="0.1"/>
      <inertia ixx="0.0001" ixy="0.0" ixz="0.0" iyy="0.0001" iyz="0.0" izz="0.0001"/>
    </inertial>

  </link>

  <joint name="w0" type="revolute">
    <origin rpy="0 0 0" xyz="0.08 0 0"/>
    <parent link="c0"/>
    <child link="d0"/>
    <axis xyz="0 1 0"/>
    <limit effort="100" lower="-3.14"  upper="3.14"  velocity="100"/>
  </joint>

  <link name="e0">
    <visual>
      <geometry>
        <sphere radius="0.02"/>
      </geometry>
      <origin rpy="0 0 0" xyz="0 0 0" />
      <material name="noir">
        <color rgba="0 0 0 1"/>
      </material>
    </visual>
    <collision>
      <geometry>
        <sphere radius="0.02"/>
      </geometry>
      <origin rpy="0 0 0" xyz="0 0 0" />
    </collision>
    <inertial>
      <mass value="0.01"/>
      <inertia ixx="0.0001" ixy="0.0" ixz="0.0" iyy="0.0001" iyz="0.0" izz="0.0001"/>
    </inertial>

  </link>

  <joint name="x0" type="fixed">
    <origin rpy="0 0 0" xyz="0.14 0 0"/>
    <parent link="d0"/>
    <child link="e0"/>
  </joint>


    <link name="h1">
    <visual>
      <geometry>
        <cylinder radius="0.01" length="0.12"/>
      </geometry>
      <origin rpy="0 1.5707963267948966 0" xyz="0.06 0  0" />
      <material name="red">
        <color rgba="1 0 0 1"/>
      </material>
    </visual>
    <collision>
      <geometry>
        <cylinder radius="0.01" length="0.12"/>
      </geometry>
      <origin rpy="0 1.5707963267948966 0" xyz="0.06 0 0" />
    </collision>
    <inertial>
      <mass value="0.1"/>
      <inertia ixx="0.0001" ixy="0.0" ixz="0.0" iyy="0.0001" iyz="0.0" izz="0.0001"/>
    </inertial>
  </link>

  <joint name="h1_to_body" type="fixed">
    <origin rpy="0 0 0" xyz="0 0 0"/>
    <parent link="body"/>
    <child link="h1"/>
  </joint>

  
  <link name="a1">
    <visual>
      <geometry>
        <cylinder radius="0.015" length="0.13"/>
      </geometry>
      <origin rpy="0 1.5707963267948966 0" xyz="0.065 0  0" />
      <material name="red">
        <color rgba="1 0 0 1"/>
      </material>
    </visual>
    <collision>
      <geometry>
        <cylinder radius="0.015" length="0.13"/>
      </geometry>
      <origin rpy="0 1.5707963267948966 0" xyz="0.065 0 0" />
    </collision>
    <inertial>
      <mass value="0.1"/>
      <inertia ixx="0.0001" ixy="0.0" ixz="0.0" iyy="0.0001" iyz="0.0" izz="0.0001"/>
    </inertial>
  </link>

  <joint name="a1_to_body" type="fixed">
    <origin rpy="0 0 2.356194490192345" xyz="0 0 0"/>
    <parent link="body"/>
    <child link="a1"/>
  </joint>

  <!-- B -->

  <link name="b1">
    <visual>
      <geometry>
        <cylinder radius="0.015" length="0.05"/>
      </geometry>
      <origin rpy="0 1.5707963267948966 0" xyz="0.025 0 0" />
      <material name="green">
        <color rgba="0 1 0 1"/>
      </material>
    </visual>
    <collision>
      <geometry>
        <cylinder radius="0.015" length="0.05"/>
      </geometry>
      <origin rpy="0 1.5707963267948966 0" xyz="0.025 0 0" />
    </collision>
    <inertial>
      <mass value="0.1"/>
      <inertia ixx="0.0001" ixy="0.0" ixz="0.0" iyy="0.0001" iyz="0.0" izz="0.0001"/>
    </inertial>

  </link>

  <joint name="u1" type="revolute">
    <origin rpy="0 0 0" xyz="0.13 0 0"/>
    <parent link="a1"/>
    <child link="b1"/>
    <axis xyz="0 0 1"/>
    <limit effort="100" lower="-3.14" upper="3.14"  velocity="100"/>
  </joint>

  <link name="c1">
    <visual>
      <geometry>
        <cylinder radius="0.015" length="0.08"/>
      </geometry>
      <origin rpy="0 1.5707963267948966 0" xyz="0.04 0 0" />
      <material name="cyan">
        <color rgba="0 1 1 1"/>
      </material>
    </visual>
    <collision>
      <geometry>
        <cylinder radius="0.015" length="0.08"/>
      </geometry>
      <origin rpy="0 1.5707963267948966 0" xyz="0.04 0 0" />
    </collision>
    <inertial>
      <mass value="0.1"/>
      <inertia ixx="0.0001" ixy="0.0" ixz="0.0" iyy="0.0001" iyz="0.0" izz="0.0001"/>
    </inertial>

  </link>

  <joint name="v1" type="revolute">
    <origin rpy="0 0 0" xyz="0.05 0 0"/>
    <parent link="b1"/>
    <child link="c1"/>
    <axis xyz="0 1 0"/>
    <limit effort="100" lower="-3.14" upper="3.14"  velocity="100"/>
  </joint>

  <link name="d1">
    <visual>
      <geometry>
        <cylinder radius="0.015" length="0.14"/>
      </geometry>
      <origin rpy="0 1.5707963267948966 0" xyz="0.07 0 0" />
      <material name="jaune">
        <color rgba="1 1 0 1"/>
      </material>
    </visual>
    <collision>
      <geometry>
        <cylinder radius="0.015" length="0.14"/>
      </geometry>
      <origin rpy="0 1.5707963267948966 0" xyz="0.07 0 0" />
    </collision>
    <inertial>
      <mass value="0.1"/>
      <inertia ixx="0.0001" ixy="0.0" ixz="0.0" iyy="0.0001" iyz="0.0" izz="0.0001"/>
    </inertial>

  </link>

  <joint name="w1" type="revolute">
    <origin rpy="0 0 0" xyz="0.08 0 0"/>
    <parent link="c1"/>
    <child link="d1"/>
    <axis xyz="0 1 0"/>
    <limit effort="100" lower="-3.14"  upper="3.14"  velocity="100"/>
  </joint>

  <link name="e1">
    <visual>
      <geometry>
        <sphere radius="0.02"/>
      </geometry>
      <origin rpy="0 0 0" xyz="0 0 0" />
      <material name="noir">
        <color rgba="0 0 0 1"/>
      </material>
    </visual>
    <collision>
      <geometry>
        <sphere radius="0.02"/>
      </geometry>
      <origin rpy="0 0 0" xyz="0 0 0" />
    </collision>
    <inertial>
      <mass value="0.01"/>
      <inertia ixx="0.0001" ixy="0.0" ixz="0.0" iyy="0.0001" iyz="0.0" izz="0.0001"/>
    </inertial>

  </link>

  <joint name="x1" type="fixed">
    <origin rpy="0 0 0" xyz="0.14 0 0"/>
    <parent link="d1"/>
    <child link="e1"/>
  </joint>


    <link name="h2">
    <visual>
      <geometry>
        <cylinder radius="0.01" length="0.12"/>
      </geometry>
      <origin rpy="0 1.5707963267948966 0" xyz="0.06 0  0" />
      <material name="red">
        <color rgba="1 0 0 1"/>
      </material>
    </visual>
    <collision>
      <geometry>
        <cylinder radius="0.01" length="0.12"/>
      </geometry>
      <origin rpy="0 1.5707963267948966 0" xyz="0.06 0 0" />
    </collision>
    <inertial>
      <mass value="0.1"/>
      <inertia ixx="0.0001" ixy="0.0" ixz="0.0" iyy="0.0001" iyz="0.0" izz="0.0001"/>
    </inertial>
  </link>

  <joint name="h2_to_body" type="fixed">
    <origin rpy="0 0 0" xyz="0 0 0"/>
    <parent link="body"/>
    <child link="h2"/>
  </joint>

  
  <link name="a2">
    <visual>
      <geometry>
        <cylinder radius="0.015" length="0.13"/>
      </geometry>
      <origin rpy="0 1.5707963267948966 0" xyz="0.065 0  0" />
      <material name="red">
        <color rgba="1 0 0 1"/>
      </material>
    </visual>
    <collision>
      <geometry>
        <cylinder radius="0.015" length="0.13"/>
      </geometry>
      <origin rpy="0 1.5707963267948966 0" xyz="0.065 0 0" />
    </collision>
    <inertial>
      <mass value="0.1"/>
      <inertia ixx="0.0001" ixy="0.0" ixz="0.0" iyy="0.0001" iyz="0.0" izz="0.0001"/>
    </inertial>
  </link>

  <joint name="a2_to_body" type="fixed">
    <origin rpy="0 0 3.9269908169872414" xyz="0 0 0"/>
    <parent link="body"/>
    <child link="a2"/>
  </joint>

  <!-- B -->

  <link name="b2">
    <visual>
      <geometry>
        <cylinder radius="0.015" length="0.05"/>
      </geometry>
      <origin rpy="0 1.5707963267948966 0" xyz="0.025 0 0" />
      <material name="green">
        <color rgba="0 1 0 1"/>
      </material>
    </visual>
    <collision>
      <geometry>
        <cylinder radius="0.015" length="0.05"/>
      </geometry>
      <origin rpy="0 1.5707963267948966 0" xyz="0.025 0 0" />
    </collision>
    <inertial>
      <mass value="0.1"/>
      <inertia ixx="0.0001" ixy="0.0" ixz="0.0" iyy="0.0001" iyz="0.0" izz="0.0001"/>
    </inertial>

  </link>

  <joint name="u2" type="revolute">
    <origin rpy="0 0 0" xyz="0.13 0 0"/>
    <parent link="a2"/>
    <child link="b2"/>
    <axis xyz="0 0 1"/>
    <limit effort="100" lower="-3.14" upper="3.14"  velocity="100"/>
  </joint>

  <link name="c2">
    <visual>
      <geometry>
        <cylinder radius="0.015" length="0.08"/>
      </geometry>
      <origin rpy="0 1.5707963267948966 0" xyz="0.04 0 0" />
      <material name="cyan">
        <color rgba="0 1 1 1"/>
      </material>
    </visual>
    <collision>
      <geometry>
        <cylinder radius="0.015" length="0.08"/>
      </geometry>
      <origin rpy="0 1.5707963267948966 0" xyz="0.04 0 0" />
    </collision>
    <inertial>
      <mass value="0.1"/>
      <inertia ixx="0.0001" ixy="0.0" ixz="0.0" iyy="0.0001" iyz="0.0" izz="0.0001"/>
    </inertial>

  </link>

  <joint name="v2" type="revolute">
    <origin rpy="0 0 0" xyz="0.05 0 0"/>
    <parent link="b2"/>
    <child link="c2"/>
    <axis xyz="0 1 0"/>
    <limit effort="100" lower="-3.14" upper="3.14"  velocity="100"/>
  </joint>

  <link name="d2">
    <visual>
      <geometry>
        <cylinder radius="0.015" length="0.14"/>
      </geometry>
      <origin rpy="0 1.5707963267948966 0" xyz="0.07 0 0" />
      <material name="jaune">
        <color rgba="1 1 0 1"/>
      </material>
    </visual>
    <collision>
      <geometry>
        <cylinder radius="0.015" length="0.14"/>
      </geometry>
      <origin rpy="0 1.5707963267948966 0" xyz="0.07 0 0" />
    </collision>
    <inertial>
      <mass value="0.1"/>
      <inertia ixx="0.0001" ixy="0.0" ixz="0.0" iyy="0.0001" iyz="0.0" izz="0.0001"/>
    </inertial>

  </link>

  <joint name="w2" type="revolute">
    <origin rpy="0 0 0" xyz="0.08 0 0"/>
    <parent link="c2"/>
    <child link="d2"/>
    <axis xyz="0 1 0"/>
    <limit effort="100" lower="-3.14"  upper="3.14"  velocity="100"/>
  </joint>

  <link name="e2">
    <visual>
      <geometry>
        <sphere radius="0.02"/>
      </geometry>
      <origin rpy="0 0 0" xyz="0 0 0" />
      <material name="noir">
        <color rgba="0 0 0 1"/>
      </material>
    </visual>
    <collision>
      <geometry>
        <sphere radius="0.02"/>
      </geometry>
      <origin rpy="0 0 0" xyz="0 0 0" />
    </collision>
    <inertial>
      <mass value="0.01"/>
      <inertia ixx="0.0001" ixy="0.0" ixz="0.0" iyy="0.0001" iyz="0.0" izz="0.0001"/>
    </inertial>

  </link>

  <joint name="x2" type="fixed">
    <origin rpy="0 0 0" xyz="0.14 0 0"/>
    <parent link="d2"/>
    <child link="e2"/>
  </joint>


    <link name="h3">
    <visual>
      <geometry>
        <cylinder radius="0.01" length="0.12"/>
      </geometry>
      <origin rpy="0 1.5707963267948966 0" xyz="0.06 0  0" />
      <material name="red">
        <color rgba="1 0 0 1"/>
      </material>
    </visual>
    <collision>
      <geometry>
        <cylinder radius="0.01" length="0.12"/>
      </geometry>
      <origin rpy="0 1.5707963267948966 0" xyz="0.06 0 0" />
    </collision>
    <inertial>
      <mass value="0.1"/>
      <inertia ixx="0.0001" ixy="0.0" ixz="0.0" iyy="0.0001" iyz="0.0" izz="0.0001"/>
    </inertial>
  </link>

  <joint name="h3_to_body" type="fixed">
    <origin rpy="0 0 0" xyz="0 0 0"/>
    <parent link="body"/>
    <child link="h3"/>
  </joint>

  
  <link name="a3">
    <visual>
      <geometry>
        <cylinder radius="0.015" length="0.13"/>
      </geometry>
      <origin rpy="0 1.5707963267948966 0" xyz="0.065 0  0" />
      <material name="red">
        <color rgba="1 0 0 1"/>
      </material>
    </visual>
    <collision>
      <geometry>
        <cylinder radius="0.015" length="0.13"/>
      </geometry>
      <origin rpy="0 1.5707963267948966 0" xyz="0.065 0 0" />
    </collision>
    <inertial>
      <mass value="0.1"/>
      <inertia ixx="0.0001" ixy="0.0" ixz="0.0" iyy="0.0001" iyz="0.0" izz="0.0001"/>
    </inertial>
  </link>

  <joint name="a3_to_body" type="fixed">
    <origin rpy="0 0 5.497787143782138" xyz="0 0 0"/>
    <parent link="body"/>
    <child link="a3"/>
  </joint>

  <!-- B -->

  <link name="b3">
    <visual>
      <geometry>
        <cylinder radius="0.015" length="0.05"/>
      </geometry>
      <origin rpy="0 1.5707963267948966 0" xyz="0.025 0 0" />
      <material name="green">
        <color rgba="0 1 0 1"/>
      </material>
    </visual>
    <collision>
      <geometry>
        <cylinder radius="0.015" length="0.05"/>
      </geometry>
      <origin rpy="0 1.5707963267948966 0" xyz="0.025 0 0" />
    </collision>
    <inertial>
      <mass value="0.1"/>
      <inertia ixx="0.0001" ixy="0.0" ixz="0.0" iyy="0.0001" iyz="0.0" izz="0.0001"/>
    </inertial>

  </link>

  <joint name="u3" type="revolute">
    <origin rpy="0 0 0" xyz="0.13 0 0"/>
    <parent link="a3"/>
    <child link="b3"/>
    <axis xyz="0 0 1"/>
    <limit effort="100" lower="-3.14" upper="3.14"  velocity="100"/>
  </joint>

  <link name="c3">
    <visual>
      <geometry>
        <cylinder radius="0.015" length="0.08"/>
      </geometry>
      <origin rpy="0 1.5707963267948966 0" xyz="0.04 0 0" />
      <material name="cyan">
        <color rgba="0 1 1 1"/>
      </material>
    </visual>
    <collision>
      <geometry>
        <cylinder radius="0.015" length="0.08"/>
      </geometry>
      <origin rpy="0 1.5707963267948966 0" xyz="0.04 0 0" />
    </collision>
    <inertial>
      <mass value="0.1"/>
      <inertia ixx="0.0001" ixy="0.0" ixz="0.0" iyy="0.0001" iyz="0.0" izz="0.0001"/>
    </inertial>

  </link>

  <joint name="v3" type="revolute">
    <origin rpy="0 0 0" xyz="0.05 0 0"/>
    <parent link="b3"/>
    <child link="c3"/>
    <axis xyz="0 1 0"/>
    <limit effort="100" lower="-3.14" upper="3.14"  velocity="100"/>
  </joint>

  <link name="d3">
    <visual>
      <geometry>
        <cylinder radius="0.015" length="0.14"/>
      </geometry>
      <origin rpy="0 1.5707963267948966 0" xyz="0.07 0 0" />
      <material name="jaune">
        <color rgba="1 1 0 1"/>
      </material>
    </visual>
    <collision>
      <geometry>
        <cylinder radius="0.015" length="0.14"/>
      </geometry>
      <origin rpy="0 1.5707963267948966 0" xyz="0.07 0 0" />
    </collision>
    <inertial>
      <mass value="0.1"/>
      <inertia ixx="0.0001" ixy="0.0" ixz="0.0" iyy="0.0001" iyz="0.0" izz="0.0001"/>
    </inertial>

  </link>

  <joint name="w3" type="revolute">
    <origin rpy="0 0 0" xyz="0.08 0 0"/>
    <parent link="c3"/>
    <child link="d3"/>
    <axis xyz="0 1 0"/>
    <limit effort="100" lower="-3.14"  upper="3.14"  velocity="100"/>
  </joint>

  <link name="e3">
    <visual>
      <geometry>
        <sphere radius="0.02"/>
      </geometry>
      <origin rpy="0 0 0" xyz="0 0 0" />
      <material name="noir">
        <color rgba="0 0 0 1"/>
      </material>
    </visual>
    <collision>
      <geometry>
        <sphere radius="0.02"/>
      </geometry>
      <origin rpy="0 0 0" xyz="0 0 0" />
    </collision>
    <inertial>
      <mass value="0.01"/>
      <inertia ixx="0.0001" ixy="0.0" ixz="0.0" iyy="0.0001" iyz="0.0" izz="0.0001"/>
    </inertial>

  </link>

  <joint name="x3" type="fixed">
    <origin rpy="0 0 0" xyz="0.14 0 0"/>
    <parent link="d3"/>
    <child link="e3"/>
  </joint>

</robot>